<?xml version="1.0"?>
<robot name="simple_robot" xmlns:xacro="http://www.ros.org/wiki/xacro">

  <!-- ===================== -->
  <!-- 参数 -->
  <!-- ===================== -->
  <xacro:property name="base_length" value="0.40"/>
  <xacro:property name="base_width"  value="0.26"/>
  <xacro:property name="base_height" value="0.08"/>

  <xacro:property name="wheel_radius" value="0.06"/>
  <xacro:property name="wheel_width"  value="0.04"/>

  <xacro:property name="laser_radius" value="0.03"/>
  <xacro:property name="laser_height" value="0.05"/>

  <!-- ===================== -->
  <!-- base_link -->
  <!-- ===================== -->
  <link name="base_link">
    <visual>
      <origin xyz="0 0 0" rpy="0 0 0"/>
      <geometry>
        <box size="${base_length} ${base_width} ${base_height}"/>
      </geometry>
      <material name="blue">
        <color rgba="0.2 0.4 0.8 1.0"/>
      </material>
    </visual>

    <collision>
      <origin xyz="0 0 0" rpy="0 0 0"/>
      <geometry>
        <box size="${base_length} ${base_width} ${base_height}"/>
      </geometry>
    </collision>

    <inertial>
      <origin xyz="0 0 0" rpy="0 0 0"/>
      <mass value="2.0"/>
      <inertia
        ixx="0.02" ixy="0.0" ixz="0.0"
        iyy="0.03" iyz="0.0"
        izz="0.04"/>
    </inertial>
  </link>

  <!-- ===================== -->
  <!-- left_wheel -->
  <!-- ===================== -->
  <link name="left_wheel">
    <visual>
      <!-- 圆柱默认沿 z 轴，转成车轮方向 -->
      <origin xyz="0 0 0" rpy="1.5708 0 0"/>
      <geometry>
        <cylinder radius="${wheel_radius}" length="${wheel_width}"/>
      </geometry>
      <material name="green">
        <color rgba="0.0 1.0 0.0 1.0"/>
      </material>
    </visual>

    <collision>
      <origin xyz="0 0 0" rpy="1.5708 0 0"/>
      <geometry>
        <cylinder radius="${wheel_radius}" length="${wheel_width}"/>
      </geometry>
    </collision>

    <inertial>
      <origin xyz="0 0 0" rpy="0 0 0"/>
      <mass value="0.3"/>
      <inertia
        ixx="0.001" ixy="0.0" ixz="0.0"
        iyy="0.001" iyz="0.0"
        izz="0.001"/>
    </inertial>
  </link>

  <!-- ===================== -->
  <!-- right_wheel -->
  <!-- ===================== -->
  <link name="right_wheel">
    <visual>
      <origin xyz="0 0 0" rpy="1.5708 0 0"/>
      <geometry>
        <cylinder radius="${wheel_radius}" length="${wheel_width}"/>
      </geometry>
      <material name="yellow">
        <color rgba="1.0 1.0 0.0 1.0"/>
      </material>
    </visual>

    <collision>
      <origin xyz="0 0 0" rpy="1.5708 0 0"/>
      <geometry>
        <cylinder radius="${wheel_radius}" length="${wheel_width}"/>
      </geometry>
    </collision>

    <inertial>
      <origin xyz="0 0 0" rpy="0 0 0"/>
      <mass value="0.3"/>
      <inertia
        ixx="0.001" ixy="0.0" ixz="0.0"
        iyy="0.001" iyz="0.0"
        izz="0.001"/>
    </inertial>
  </link>

  <!-- ===================== -->
  <!-- laser_link -->
  <!-- ===================== -->
  <link name="laser_link">
    <visual>
      <origin xyz="0 0 0" rpy="0 0 0"/>
      <geometry>
        <cylinder radius="${laser_radius}" length="${laser_height}"/>
      </geometry>
      <material name="red">
        <color rgba="1.0 0.0 0.0 1.0"/>
      </material>
    </visual>

    <collision>
      <origin xyz="0 0 0" rpy="0 0 0"/>
      <geometry>
        <cylinder radius="${laser_radius}" length="${laser_height}"/>
      </geometry>
    </collision>

    <inertial>
      <origin xyz="0 0 0" rpy="0 0 0"/>
      <mass value="0.1"/>
      <inertia
        ixx="0.0001" ixy="0.0" ixz="0.0"
        iyy="0.0001" iyz="0.0"
        izz="0.0001"/>
    </inertial>
  </link>

  <!-- ===================== -->
  <!-- joints -->
  <!-- ===================== -->
 <joint name="left_wheel_joint" type="continuous">
  <parent link="base_link"/>
  <child link="left_wheel"/>
  <origin xyz="0 0.15 -0.04" rpy="0 0 0"/>
  <axis xyz="0 1 0"/>
 </joint>

 <joint name="right_wheel_joint" type="continuous">
  <parent link="base_link"/>
  <child link="right_wheel"/>
  <origin xyz="0 -0.15 -0.04" rpy="0 0 0"/>
  <axis xyz="0 1 0"/>
 </joint>

  <joint name="base_to_laser" type="fixed">
    <parent link="base_link"/>
    <child link="laser_link"/>
    <origin xyz="0.14 0 0.07" rpy="0 0 0"/>
  </joint>

  <!-- ===================== -->
  <!-- Gazebo diff drive -->
  <!-- ===================== -->
  <gazebo>
   <plugin
    filename="gz-sim-diff-drive-system"
    name="gz::sim::systems::DiffDrive">
    <left_joint>left_wheel_joint</left_joint>
    <right_joint>right_wheel_joint</right_joint>
    <wheel_separation>0.30</wheel_separation>
    <wheel_radius>0.06</wheel_radius>
    <topic>/model/simple_robot/cmd_vel</topic>
   </plugin>
  </gazebo>
  <!-- ===================== -->
  <!-- Gazebo 激光雷达传感器 -->
  <!-- ===================== -->
  <gazebo reference="laser_link">
    <sensor name="laser_sensor" type="gpu_lidar">
      <pose>0 0 0.05 0 0 0</pose>
      <always_on>1</always_on>
      <update_rate>10</update_rate>
      <visualize>true</visualize>
      <topic>/scan</topic>

      <lidar>
        <scan>
          <horizontal>
            <samples>360</samples>
            <resolution>1</resolution>
            <min_angle>-1.5708</min_angle>
            <max_angle>1.5708</max_angle>
          </horizontal>
        </scan>

        <range>
          <min>0.15</min>
          <max>6.0</max>
          <resolution>0.01</resolution>
        </range>

        <noise>
          <type>gaussian</type>
          <mean>0.0</mean>
          <stddev>0.01</stddev>
        </noise>
      </lidar>
    </sensor>
  </gazebo>

</robot>
